Workbook

Sheet Dashboard
B1: Commercial Maturity Scoring Tool
B2: Dashboard — Team (Axis A) vs Business (Axis B)
B4: DIMENSION SUMMARY | G4: Dimension | H4: Team (A) | I4: Business (B)
B5: Dimension | C5: Team (Axis A) | D5: Business (Axis B) | E5: Gap (A – B) | G5: Strategy | H5: =C6 -> 3 | I5: =D6 -> 2.5
B6: Commercial Strategy & Alignment | C6: ='Team Assessment (Axis A)'!D42 -> 3 | D6: ='Business Assessment (Axis B)'!D42 -> 2.5 | E6: =IFERROR(C6-D6,"") -> 0.5 | G6: Process | H6: =C7 | I6: =D7
B7: Processes & Governance | C7: ='Team Assessment (Axis A)'!D43 | D7: ='Business Assessment (Axis B)'!D43 | E7: =IFERROR(C7-D7,"") | G7: Data | H7: =C8 | I7: =D8
B8: Data & Analytics | C8: ='Team Assessment (Axis A)'!D44 | D8: ='Business Assessment (Axis B)'!D44 | E8: =IFERROR(C8-D8,"") | G8: Capability | H8: =C9 | I8: =D9
B9: Capabilities & Expertise | C9: ='Team Assessment (Axis A)'!D45 | D9: ='Business Assessment (Axis B)'!D45 | E9: =IFERROR(C9-D9,"") | G9: Collaboration | H9: =C10 | I9: =D10
B10: Cross-Functional Collaboration & Enablement | C10: ='Team Assessment (Axis A)'!D46 | D10: ='Business Assessment (Axis B)'!D46 | E10: =IFERROR(C10-D10,"")
B11: OVERALL AVERAGE | C11: =IFERROR(AVERAGE(C6:C10),"") -> 3 | D11: =IFERROR(AVERAGE(D6:D10),"") -> 2.5 | E11: =IFERROR(AVERAGE(E6:E10),"") -> 0.5
B37: DETAILED HEATMAP — 30 Sub-Categories
B38: # | C38: Sub-category | D38: Team (A) | E38: Business (B) | F38: Gap
B39: Commercial Strategy & Alignment
B40: 1.1 | C40: Strategic Clarity | D40: ='Team Assessment (Axis A)'!D6 -> 3 | E40: ='Business Assessment (Axis B)'!D6 -> 2 | F40: =IFERROR(D40-E40,"") -> 1
B41: 1.2 | C41: Portfolio Alignment | D41: ='Team Assessment (Axis A)'!D7 -> 3 | E41: ='Business Assessment (Axis B)'!D7 -> 3 | F41: =IFERROR(D41-E41,"") -> 0
B42: 1.3 | C42: Value Proposition & Monetization Fit | D42: ='Team Assessment (Axis A)'!D8 -> 0 | E42: ='Business Assessment (Axis B)'!D8 -> 0 | F42: =IFERROR(D42-E42,"") -> 0
B43: 1.4 | C43: Ownership & Accountability | D43: ='Team Assessment (Axis A)'!D9 -> 0 | E43: ='Business Assessment (Axis B)'!D9 -> 0 | F43: =IFERROR(D43-E43,"") -> 0
B44: 1.5 | C44: Strategic Prioritization | D44: ='Team Assessment (Axis A)'!D10 -> 0 | E44: ='Business Assessment (Axis B)'!D10 -> 0 | F44: =IFERROR(D44-E44,"") -> 0
B45: 1.6 | C45: Future Readiness | D45: ='Team Assessment (Axis A)'!D11 -> 0 | E45: ='Business Assessment (Axis B)'!D11 -> 0 | F45: =IFERROR(D45-E45,"") -> 0
B46: Processes & Governance
B47: 2.1 | C47: Governance Structure | D47: ='Team Assessment (Axis A)'!D13 -> 0 | E47: ='Business Assessment (Axis B)'!D13 -> 0 | F47: =IFERROR(D47-E47,"") -> 0
B48: 2.2 | C48: Initiative Lifecycle Management | D48: ='Team Assessment (Axis A)'!D14 -> 0 | E48: ='Business Assessment (Axis B)'!D14 -> 0 | F48: =IFERROR(D48-E48,"") -> 0
B49: 2.3 | C49: Decision Rights & Escalation | D49: ='Team Assessment (Axis A)'!D15 -> 0 | E49: ='Business Assessment (Axis B)'!D15 -> 0 | F49: =IFERROR(D49-E49,"") -> 0
B50: 2.4 | C50: Policy & Compliance Adherence | D50: ='Team Assessment (Axis A)'!D16 -> 0 | E50: ='Business Assessment (Axis B)'!D16 -> 0 | F50: =IFERROR(D50-E50,"") -> 0
B51: 2.5 | C51: Documentation & Auditability | D51: ='Team Assessment (Axis A)'!D17 -> 0 | E51: ='Business Assessment (Axis B)'!D17 -> 0 | F51: =IFERROR(D51-E51,"") -> 0
B52: 2.6 | C52: Continuous Improvement | D52: ='Team Assessment (Axis A)'!D18 -> 0 | E52: ='Business Assessment (Axis B)'!D18 -> 0 | F52: =IFERROR(D52-E52,"") -> 0
B53: Data & Analytics
B54: 3.1 | C54: Data Quality & Availability | D54: ='Team Assessment (Axis A)'!D20 -> 0 | E54: ='Business Assessment (Axis B)'!D20 -> 0 | F54: =IFERROR(D54-E54,"") -> 0
B55: 3.2 | C55: Dashboard Utilization | D55: ='Team Assessment (Axis A)'!D21 -> 0 | E55: ='Business Assessment (Axis B)'!D21 -> 0 | F55: =IFERROR(D55-E55,"") -> 0
B56: 3.3 | C56: KPI Definition & Ownership | D56: ='Team Assessment (Axis A)'!D22 -> 0 | E56: ='Business Assessment (Axis B)'!D22 -> 0 | F56: =IFERROR(D56-E56,"") -> 0
B57: 3.4 | C57: Analytical Capabilities | D57: ='Team Assessment (Axis A)'!D23 -> 0 | E57: ='Business Assessment (Axis B)'!D23 -> 0 | F57: =IFERROR(D57-E57,"") -> 0
B58: 3.5 | C58: Data-Driven Culture | D58: ='Team Assessment (Axis A)'!D24 -> 0 | E58: ='Business Assessment (Axis B)'!D24 -> 0 | F58: =IFERROR(D58-E58,"") -> 0
B59: 3.6 | C59: Reporting Integration & Automation | D59: ='Team Assessment (Axis A)'!D25 -> 0 | E59: ='Business Assessment (Axis B)'!D25 -> 0 | F59: =IFERROR(D59-E59,"") -> 0
B60: Capabilities & Expertise
B61: 4.1 | C61: Commercial Acumen & Skillset | D61: ='Team Assessment (Axis A)'!D27 -> 0 | E61: ='Business Assessment (Axis B)'!D27 -> 0 | F61: =IFERROR(D61-E61,"") -> 0
B62: 4.2 | C62: Functional Independence | D62: ='Team Assessment (Axis A)'!D28 -> 0 | E62: ='Business Assessment (Axis B)'!D28 -> 0 | F62: =IFERROR(D62-E62,"") -> 0
B63: 4.3 | C63: Business Partnering Skills | D63: ='Team Assessment (Axis A)'!D29 -> 0 | E63: ='Business Assessment (Axis B)'!D29 -> 0 | F63: =IFERROR(D63-E63,"") -> 0
B64: 4.4 | C64: Learning & Development | D64: ='Team Assessment (Axis A)'!D30 -> 0 | E64: ='Business Assessment (Axis B)'!D30 -> 0 | F64: =IFERROR(D64-E64,"") -> 0
B65: 4.5 | C65: Talent Management & Succession | D65: ='Team Assessment (Axis A)'!D31 -> 0 | E65: ='Business Assessment (Axis B)'!D31 -> 0 | F65: =IFERROR(D65-E65,"") -> 0
B66: 4.6 | C66: Innovation & Agility | D66: ='Team Assessment (Axis A)'!D32 -> 0 | E66: ='Business Assessment (Axis B)'!D32 -> 0 | F66: =IFERROR(D66-E66,"") -> 0
...

Sheet Team Assessment (Axis A)
A1: Team Maturity Assessment (Axis A)
A2: Score each sub-category from 1 (Reactive) to 5 (Strategic). Use the Rubric Reference sheet and the Scoring Rubric document for criteria.
A3: Link to the detailed criteria doc: https://ifs.sharepoint.com/teams/IFSGroupCommercial/Shared%20Documents/Group%20Commercial%20Folder/Maturity%20Matrix/Appx%201%20-%20Detailed%20questions%20-%20Commercial%20Maturity%20Matrix.docx?web=1
A4: Dimension | B4: # | C4: Sub-category | D4: Score (1-5) | E4: Evidence / KPIs | F4: Strengths | G4: Gaps | H4: Next Steps | I4: Owner | J4: Target Date
A5: Commercial Strategy & Alignment
A6: Commercial Strategy & Alignment | B6: 1.1 | C6: Strategic Clarity | D6: 3 | E6: Monthly reviews, weekly alignment on priorities. Documentation through Confluence - made available for immediate stakeholders. Regular syncs with Deal Desk, Legal, R&D Operations, Finance
A7: Commercial Strategy & Alignment | B7: 1.2 | C7: Portfolio Alignment | D7: 3
A8: Commercial Strategy & Alignment | B8: 1.3 | C8: Value Proposition & Monetization Fit
A9: Commercial Strategy & Alignment | B9: 1.4 | C9: Ownership & Accountability
A10: Commercial Strategy & Alignment | B10: 1.5 | C10: Strategic Prioritization
A11: Commercial Strategy & Alignment | B11: 1.6 | C11: Future Readiness
A12: Processes & Governance
A13: Processes & Governance | B13: 2.1 | C13: Governance Structure
A14: Processes & Governance | B14: 2.2 | C14: Initiative Lifecycle Management
A15: Processes & Governance | B15: 2.3 | C15: Decision Rights & Escalation
A16: Processes & Governance | B16: 2.4 | C16: Policy & Compliance Adherence
A17: Processes & Governance | B17: 2.5 | C17: Documentation & Auditability
A18: Processes & Governance | B18: 2.6 | C18: Continuous Improvement
A19: Data & Analytics
A20: Data & Analytics | B20: 3.1 | C20: Data Quality & Availability
A21: Data & Analytics | B21: 3.2 | C21: Dashboard Utilization
A22: Data & Analytics | B22: 3.3 | C22: KPI Definition & Ownership
A23: Data & Analytics | B23: 3.4 | C23: Analytical Capabilities
A24: Data & Analytics | B24: 3.5 | C24: Data-Driven Culture
A25: Data & Analytics | B25: 3.6 | C25: Reporting Integration & Automation
A26: Capabilities & Expertise
A27: Capabilities & Expertise | B27: 4.1 | C27: Commercial Acumen & Skillset
A28: Capabilities & Expertise | B28: 4.2 | C28: Functional Independence
A29: Capabilities & Expertise | B29: 4.3 | C29: Business Partnering Skills
A30: Capabilities & Expertise | B30: 4.4 | C30: Learning & Development
A31: Capabilities & Expertise | B31: 4.5 | C31: Talent Management & Succession
A32: Capabilities & Expertise | B32: 4.6 | C32: Innovation & Agility
A33: Cross-Functional Collaboration & Enablement
A34: Cross-Functional Collaboration & Enablement | B34: 5.1 | C34: Role Clarity Across Functions
A35: Cross-Functional Collaboration & Enablement | B35: 5.2 | C35: Joint Planning & Decision-Making
A36: Cross-Functional Collaboration & Enablement | B36: 5.3 | C36: Communication & Transparency
A37: Cross-Functional Collaboration & Enablement | B37: 5.4 | C37: Enablement & Training
A38: Cross-Functional Collaboration & Enablement | B38: 5.5 | C38: Escalation & Conflict Resolution
A39: Cross-Functional Collaboration & Enablement | B39: 5.6 | C39: Customer & Market Feedback Loop
A41: DIMENSION AVERAGES
...

Sheet Business Assessment (Axis B)
A1: Business Maturity Assessment (Axis B)
A2: Score each sub-category from 1 (Reactive) to 5 (Strategic). Use the Rubric Reference sheet and the Scoring Rubric document for criteria.
A3: Link to the detailed criteria doc: https://ifs.sharepoint.com/teams/IFSGroupCommercial/Shared%20Documents/Group%20Commercial%20Folder/Maturity%20Matrix/Appx%201%20-%20Detailed%20questions%20-%20Commercial%20Maturity%20Matrix.docx?web=1
A4: Dimension | B4: # | C4: Sub-category | D4: Score (1-5) | E4: Evidence / KPIs | F4: Strengths | G4: Gaps | H4: Next Steps | I4: Owner | J4: Target Date
A5: Commercial Strategy & Alignment
A6: Commercial Strategy & Alignment | B6: 1.1 | C6: Strategic Clarity | D6: 2 | E6: Lacking defined success metric for each priotities (improvement, not qualify as 3) | F6: High frequency of reviewed priorities, communication and alignment through monthly Commm Council and regular syncs | G6: Cascading priorities/communication, linkage to measurable outcomes
A7: Commercial Strategy & Alignment | B7: 1.2 | C7: Portfolio Alignment | D7: 3 | E7: Process has just been overhauled, link https://ifsdev.atlassian.net/wiki/spaces/ROB/pages/3151364304/Investment+Pitch-deck. Product Council approving each new investment. On a way to move to a higher scope next year
A8: Commercial Strategy & Alignment | B8: 1.3 | C8: Value Proposition & Monetization Fit
A9: Commercial Strategy & Alignment | B9: 1.4 | C9: Ownership & Accountability
A10: Commercial Strategy & Alignment | B10: 1.5 | C10: Strategic Prioritization
A11: Commercial Strategy & Alignment | B11: 1.6 | C11: Future Readiness
A12: Processes & Governance
A13: Processes & Governance | B13: 2.1 | C13: Governance Structure
A14: Processes & Governance | B14: 2.2 | C14: Initiative Lifecycle Management
A15: Processes & Governance | B15: 2.3 | C15: Decision Rights & Escalation
A16: Processes & Governance | B16: 2.4 | C16: Policy & Compliance Adherence
A17: Processes & Governance | B17: 2.5 | C17: Documentation & Auditability
A18: Processes & Governance | B18: 2.6 | C18: Continuous Improvement
A19: Data & Analytics
A20: Data & Analytics | B20: 3.1 | C20: Data Quality & Availability
A21: Data & Analytics | B21: 3.2 | C21: Dashboard Utilization
A22: Data & Analytics | B22: 3.3 | C22: KPI Definition & Ownership
A23: Data & Analytics | B23: 3.4 | C23: Analytical Capabilities
A24: Data & Analytics | B24: 3.5 | C24: Data-Driven Culture
A25: Data & Analytics | B25: 3.6 | C25: Reporting Integration & Automation
A26: Capabilities & Expertise
A27: Capabilities & Expertise | B27: 4.1 | C27: Commercial Acumen & Skillset
A28: Capabilities & Expertise | B28: 4.2 | C28: Functional Independence
A29: Capabilities & Expertise | B29: 4.3 | C29: Business Partnering Skills
A30: Capabilities & Expertise | B30: 4.4 | C30: Learning & Development
A31: Capabilities & Expertise | B31: 4.5 | C31: Talent Management & Succession
A32: Capabilities & Expertise | B32: 4.6 | C32: Innovation & Agility
A33: Cross-Functional Collaboration & Enablement
A34: Cross-Functional Collaboration & Enablement | B34: 5.1 | C34: Role Clarity Across Functions
A35: Cross-Functional Collaboration & Enablement | B35: 5.2 | C35: Joint Planning & Decision-Making
A36: Cross-Functional Collaboration & Enablement | B36: 5.3 | C36: Communication & Transparency
A37: Cross-Functional Collaboration & Enablement | B37: 5.4 | C37: Enablement & Training
A38: Cross-Functional Collaboration & Enablement | B38: 5.5 | C38: Escalation & Conflict Resolution
A39: Cross-Functional Collaboration & Enablement | B39: 5.6 | C39: Customer & Market Feedback Loop
A41: DIMENSION AVERAGES
...

Sheet Rubric Reference
A1: Rubric Quick Reference
A2: SCORING RULE: Score at the highest level where ALL criteria are met. If partial, score one level below and flag unmet criteria as "in progress."
A4: MATURITY LEVELS
A5: Level | B5: Name | C5: Core Behaviour
A6: L1 | B6: Reactive (Chaos) | C6: We sell what we have
A7: L2 | B7: Controlled (Clean Pipes) | C7: No rogue deals — stop value leakage
A8: L3 | B8: Efficient (Velocity) | C8: Salespeople spend time selling, not configuring
A9: L4 | B9: Optimized (Value Capture) | C9: We price the customer, not just the product
A10: L5 | B10: Strategic / Dynamic | C10: The system suggests the optimal price
A13: ALL 30 SUB-CATEGORIES
A14: # | B14: Sub-category | C14: Dimension
A15: Commercial Strategy & Alignment
A16: 1.1 | B16: Strategic Clarity | C16: Commercial Strategy & Alignment
A17: 1.2 | B17: Portfolio Alignment | C17: Commercial Strategy & Alignment
A18: 1.3 | B18: Value Proposition & Monetization Fit | C18: Commercial Strategy & Alignment
A19: 1.4 | B19: Ownership & Accountability | C19: Commercial Strategy & Alignment
A20: 1.5 | B20: Strategic Prioritization | C20: Commercial Strategy & Alignment
A21: 1.6 | B21: Future Readiness | C21: Commercial Strategy & Alignment
A22: Processes & Governance
A23: 2.1 | B23: Governance Structure | C23: Processes & Governance
A24: 2.2 | B24: Initiative Lifecycle Management | C24: Processes & Governance
A25: 2.3 | B25: Decision Rights & Escalation | C25: Processes & Governance
A26: 2.4 | B26: Policy & Compliance Adherence | C26: Processes & Governance
A27: 2.5 | B27: Documentation & Auditability | C27: Processes & Governance
A28: 2.6 | B28: Continuous Improvement | C28: Processes & Governance
A29: Data & Analytics
A30: 3.1 | B30: Data Quality & Availability | C30: Data & Analytics
A31: 3.2 | B31: Dashboard Utilization | C31: Data & Analytics
A32: 3.3 | B32: KPI Definition & Ownership | C32: Data & Analytics
A33: 3.4 | B33: Analytical Capabilities | C33: Data & Analytics
A34: 3.5 | B34: Data-Driven Culture | C34: Data & Analytics
A35: 3.6 | B35: Reporting Integration & Automation | C35: Data & Analytics
A36: Capabilities & Expertise
A37: 4.1 | B37: Commercial Acumen & Skillset | C37: Capabilities & Expertise
A38: 4.2 | B38: Functional Independence | C38: Capabilities & Expertise
A39: 4.3 | B39: Business Partnering Skills | C39: Capabilities & Expertise
A40: 4.4 | B40: Learning & Development | C40: Capabilities & Expertise
A41: 4.5 | B41: Talent Management & Succession | C41: Capabilities & Expertise
A42: 4.6 | B42: Innovation & Agility | C42: Capabilities & Expertise
A43: Cross-Functional Collaboration & Enablement
...
